Workbook

Sheet Executive_Dashboard
A1: FOOD DELIVERY BUSINESS ANALYTICS & PERFORMANCE OPTIMIZATION DASHBOARD
A3: Comprehensive Performance Monitoring, Diagnostic Analytics & Prescriptive Business Strategy | FY 2025
B5: TOTAL ORDERS | D5: DELIVERED ORDERS | F5: CANCELLATION RATE | H5: GROSS MERCHANDISE VALUE | J5: PLATFORM REVENUE | L5: AVG DELIVERY TIME
B6: =COUNT(Cleaned_Orders!A2:A2001) | D6: =COUNTIF(Cleaned_Orders!P2:P2001, "Delivered") | F6: =COUNTIF(Cleaned_Orders!P2:P2001, "Cancelled")/B6 | H6: =SUM(Cleaned_Orders!I2:I2001) | J6: =SUM(Cleaned_Orders!M2:M2001) | L6: =AVERAGE(Cleaned_Orders!N2:N2001)
B9: Monthly Order & Revenue Trend (Descriptive Analysis) | J9: City Market Share & Efficiency
B10: Month | C10: Year-Month | D10: Total Orders | E10: Delivered Orders | F10: GMV (INR) | G10: Platform Revenue (INR) | H10: Avg Deliv Time | J10: City | K10: Orders | L10: Revenue (INR) | M10: Avg Rating
B11: Jan 2025 | C11: 2025-01 | D11: =COUNTIF(Cleaned_Orders!R2:R2001, "2025-01") | E11: =COUNTIFS(Cleaned_Orders!R2:R2001, "2025-01", Cleaned_Orders!P2:P2001, "Delivered") | F11: =SUMIF(Cleaned_Orders!R2:R2001, "2025-01", Cleaned_Orders!I2:I2001) | G11: =SUMIF(Cleaned_Orders!R2:R2001, "2025-01", Cleaned_Orders!M2:M2001) | H11: =AVERAGEIFS(Cleaned_Orders!N2:N2001, Cleaned_Orders!R2:R2001, "2025-01") | J11: Bangalore | K11: =Pivot_Summaries!B5 | L11: =Pivot_Summaries!F5 | M11: =Pivot_Summaries!H5
B12: Feb 2025 | C12: 2025-02 | D12: =COUNTIF(Cleaned_Orders!R2:R2001, "2025-02") | E12: =COUNTIFS(Cleaned_Orders!R2:R2001, "2025-02", Cleaned_Orders!P2:P2001, "Delivered") | F12: =SUMIF(Cleaned_Orders!R2:R2001, "2025-02", Cleaned_Orders!I2:I2001) | G12: =SUMIF(Cleaned_Orders!R2:R2001, "2025-02", Cleaned_Orders!M2:M2001) | H12: =AVERAGEIFS(Cleaned_Orders!N2:N2001, Cleaned_Orders!R2:R2001, "2025-02") | J12: Mumbai | K12: =Pivot_Summaries!B6 | L12: =Pivot_Summaries!F6 | M12: =Pivot_Summaries!H6
B13: Mar 2025 | C13: 2025-03 | D13: =COUNTIF(Cleaned_Orders!R2:R2001, "2025-03") | E13: =COUNTIFS(Cleaned_Orders!R2:R2001, "2025-03", Cleaned_Orders!P2:P2001, "Delivered") | F13: =SUMIF(Cleaned_Orders!R2:R2001, "2025-03", Cleaned_Orders!I2:I2001) | G13: =SUMIF(Cleaned_Orders!R2:R2001, "2025-03", Cleaned_Orders!M2:M2001) | H13: =AVERAGEIFS(Cleaned_Orders!N2:N2001, Cleaned_Orders!R2:R2001, "2025-03") | J13: Delhi NCR | K13: =Pivot_Summaries!B7 | L13: =Pivot_Summaries!F7 | M13: =Pivot_Summaries!H7
B14: Apr 2025 | C14: 2025-04 | D14: =COUNTIF(Cleaned_Orders!R2:R2001, "2025-04") | E14: =COUNTIFS(Cleaned_Orders!R2:R2001, "2025-04", Cleaned_Orders!P2:P2001, "Delivered") | F14: =SUMIF(Cleaned_Orders!R2:R2001, "2025-04", Cleaned_Orders!I2:I2001) | G14: =SUMIF(Cleaned_Orders!R2:R2001, "2025-04", Cleaned_Orders!M2:M2001) | H14: =AVERAGEIFS(Cleaned_Orders!N2:N2001, Cleaned_Orders!R2:R2001, "2025-04") | J14: Hyderabad | K14: =Pivot_Summaries!B8 | L14: =Pivot_Summaries!F8 | M14: =Pivot_Summaries!H8
B15: May 2025 | C15: 2025-05 | D15: =COUNTIF(Cleaned_Orders!R2:R2001, "2025-05") | E15: =COUNTIFS(Cleaned_Orders!R2:R2001, "2025-05", Cleaned_Orders!P2:P2001, "Delivered") | F15: =SUMIF(Cleaned_Orders!R2:R2001, "2025-05", Cleaned_Orders!I2:I2001) | G15: =SUMIF(Cleaned_Orders!R2:R2001, "2025-05", Cleaned_Orders!M2:M2001) | H15: =AVERAGEIFS(Cleaned_Orders!N2:N2001, Cleaned_Orders!R2:R2001, "2025-05") | J15: Pune | K15: =Pivot_Summaries!B9 | L15: =Pivot_Summaries!F9 | M15: =Pivot_Summaries!H9
B16: Jun 2025 | C16: 2025-06 | D16: =COUNTIF(Cleaned_Orders!R2:R2001, "2025-06") | E16: =COUNTIFS(Cleaned_Orders!R2:R2001, "2025-06", Cleaned_Orders!P2:P2001, "Delivered") | F16: =SUMIF(Cleaned_Orders!R2:R2001, "2025-06", Cleaned_Orders!I2:I2001) | G16: =SUMIF(Cleaned_Orders!R2:R2001, "2025-06", Cleaned_Orders!M2:M2001) | H16: =AVERAGEIFS(Cleaned_Orders!N2:N2001, Cleaned_Orders!R2:R2001, "2025-06")
B17: Jul 2025 | C17: 2025-07 | D17: =COUNTIF(Cleaned_Orders!R2:R2001, "2025-07") | E17: =COUNTIFS(Cleaned_Orders!R2:R2001, "2025-07", Cleaned_Orders!P2:P2001, "Delivered") | F17: =SUMIF(Cleaned_Orders!R2:R2001, "2025-07", Cleaned_Orders!I2:I2001) | G17: =SUMIF(Cleaned_Orders!R2:R2001, "2025-07", Cleaned_Orders!M2:M2001) | H17: =AVERAGEIFS(Cleaned_Orders!N2:N2001, Cleaned_Orders!R2:R2001, "2025-07") | J17: System Operational Health & Outlier Monitor
B18: Aug 2025 | C18: 2025-08 | D18: =COUNTIF(Cleaned_Orders!R2:R2001, "2025-08") | E18: =COUNTIFS(Cleaned_Orders!R2:R2001, "2025-08", Cleaned_Orders!P2:P2001, "Delivered") | F18: =SUMIF(Cleaned_Orders!R2:R2001, "2025-08", Cleaned_Orders!I2:I2001) | G18: =SUMIF(Cleaned_Orders!R2:R2001, "2025-08", Cleaned_Orders!M2:M2001) | H18: =AVERAGEIFS(Cleaned_Orders!N2:N2001, Cleaned_Orders!R2:R2001, "2025-08") | J18: Average Delivery Time | M18: =Statistical_Analysis!B5
B19: Sep 2025 | C19: 2025-09 | D19: =COUNTIF(Cleaned_Orders!R2:R2001, "2025-09") | E19: =COUNTIFS(Cleaned_Orders!R2:R2001, "2025-09", Cleaned_Orders!P2:P2001, "Delivered") | F19: =SUMIF(Cleaned_Orders!R2:R2001, "2025-09", Cleaned_Orders!I2:I2001) | G19: =SUMIF(Cleaned_Orders!R2:R2001, "2025-09", Cleaned_Orders!M2:M2001) | H19: =AVERAGEIFS(Cleaned_Orders!N2:N2001, Cleaned_Orders!R2:R2001, "2025-09") | J19: Median Delivery Time | M19: =Statistical_Analysis!B6
B20: Oct 2025 | C20: 2025-10 | D20: =COUNTIF(Cleaned_Orders!R2:R2001, "2025-10") | E20: =COUNTIFS(Cleaned_Orders!R2:R2001, "2025-10", Cleaned_Orders!P2:P2001, "Delivered") | F20: =SUMIF(Cleaned_Orders!R2:R2001, "2025-10", Cleaned_Orders!I2:I2001) | G20: =SUMIF(Cleaned_Orders!R2:R2001, "2025-10", Cleaned_Orders!M2:M2001) | H20: =AVERAGEIFS(Cleaned_Orders!N2:N2001, Cleaned_Orders!R2:R2001, "2025-10") | J20: IQR Delivery Spread (Q3-Q1) | M20: =Statistical_Analysis!B14
B21: Nov 2025 | C21: 2025-11 | D21: =COUNTIF(Cleaned_Orders!R2:R2001, "2025-11") | E21: =COUNTIFS(Cleaned_Orders!R2:R2001, "2025-11", Cleaned_Orders!P2:P2001, "Delivered") | F21: =SUMIF(Cleaned_Orders!R2:R2001, "2025-11", Cleaned_Orders!I2:I2001) | G21: =SUMIF(Cleaned_Orders!R2:R2001, "2025-11", Cleaned_Orders!M2:M2001) | H21: =AVERAGEIFS(Cleaned_Orders!N2:N2001, Cleaned_Orders!R2:R2001, "2025-11") | J21: Extreme Delay Outliers (> Upper Bound) | M21: =Statistical_Analysis!B18
B22: Dec 2025 | C22: 2025-12 | D22: =COUNTIF(Cleaned_Orders!R2:R2001, "2025-12") | E22: =COUNTIFS(Cleaned_Orders!R2:R2001, "2025-12", Cleaned_Orders!P2:P2001, "Delivered") | F22: =SUMIF(Cleaned_Orders!R2:R2001, "2025-12", Cleaned_Orders!I2:I2001) | G22: =SUMIF(Cleaned_Orders!R2:R2001, "2025-12", Cleaned_Orders!M2:M2001) | H22: =AVERAGEIFS(Cleaned_Orders!N2:N2001, Cleaned_Orders!R2:R2001, "2025-12") | J22: High Risk / Low Rated Orders | M22: =COUNTIF(Cleaned_Orders!U2:U2001, "High Risk / Delayed")
B24: Prescriptive Analytics & Business Recommendations (Action Plan)
B25: 1. Peak Hour Delivery Rebalancing: | C25: Deploy 25% surge partner incentives in Bangalore & Mumbai between 19:00 - 21:30 to eliminate delivery bottlenecks and reduce outlier delays.
B26: 2. Kitchen Delay SLA Enforcement: | C26: Enforce a maximum 18-minute food preparation SLA for high-volume Biryani & Italian partners where kitchen delays account for over 50% of late deliveries.
B27: 3. Long-Distance Cancellation Mitigation: | C27: Cap standard delivery radius to 10 km during rain and peak rush hours; orders over 10 km exhibit 3.4x higher cancellation and sub-3.0 customer ratings.
B28: 4. Loyalty Tier Value Optimization: | C28: Re-evaluate free delivery threshold for Gold members; currently accounts for ₹120,000+ subsidized delivery cost, offset by maintaining minimum order spend of ₹599.
B29: 5. Low-Rated Restaurant Service Intervention: | C29: Trigger mandatory quality audits and menu review for restaurants averaging < 3.8 rating (e.g., Dragon Bowl, Tandoori Nights) to prevent customer churn.

Sheet Customers
A1: customer_id | B1: customer_name | C1: city | D1: loyalty_tier | E1: age | F1: gender
A2: 1001 | B2: Customer_1001 | C2: Hyderabad | D2: Regular | E2: 47 | F2: Male
A3: 1002 | B3: Customer_1002 | C3: Delhi NCR | D3: Gold | E3: 26 | F3: Male
A4: 1003 | B4: Customer_1003 | C4: Pune | D4: Silver | E4: 52 | F4: Female
A5: 1004 | B5: Customer_1004 | C5: Pune | D5: Regular | E5: 45 | F5: Other
A6: 1005 | B6: Customer_1005 | C6: Hyderabad | D6: Regular | E6: 41 | F6: Male
A7: 1006 | B7: Customer_1006 | C7: Mumbai | D7: Regular | E7: 50 | F7: Female
A8: 1007 | B8: Customer_1007 | C8: Bangalore | D8: Regular | E8: 21 | F8: Male
A9: 1008 | B9: Customer_1008 | C9: Mumbai | D9: Gold | E9: 58 | F9: Male
A10: 1009 | B10: Customer_1009 | C10: Hyderabad | D10: Silver | E10: 56 | F10: Male
A11: 1010 | B11: Customer_1010 | C11: Hyderabad | D11: Silver | E11: 42 | F11: Other
A12: 1011 | B12: Customer_1011 | C12: Hyderabad | D12: Regular | E12: 51 | F12: Female
A13: 1012 | B13: Customer_1012 | C13: Pune | D13: Gold | E13: 18 | F13: Other
... A301: 1300 | B301: Customer_1300 | C301: Delhi NCR | D301: Regular | E301: 38 | F301: Male

Sheet Restaurants
A1: restaurant_id | B1: restaurant_name | C1: city | D1: cuisine_category | E1: avg_rating | F1: commission_rate
A2: 101 | B2: Spice Hub | C2: Bangalore | D2: North Indian | E2: 4.3 | F2: 0.2
A3: 102 | B3: Royal Biryani Mahal | C3: Hyderabad | D3: Biryani | E3: 4.6 | F3: 0.22
A4: 103 | B4: Pizza Fiesta | C4: Mumbai | D4: Italian | E4: 4.1 | F4: 0.18
A5: 104 | B5: Burger Junction | C5: Delhi NCR | D5: Fast Food | E5: 4.2 | F5: 0.18
A6: 105 | B6: Wok Express | C6: Bangalore | D6: Chinese | E6: 3.9 | F6: 0.2
A7: 106 | B7: Green Leaf Veg | C7: Pune | D7: South Indian | E7: 4.5 | F7: 0.15
A8: 107 | B8: Sweet Tooth Bakery | C8: Mumbai | D8: Desserts | E8: 4.7 | F8: 0.25
A9: 108 | B9: Dilli 6 Chaat Corner | C9: Delhi NCR | D9: Fast Food | E9: 4.4 | F9: 0.18
A10: 109 | B10: Hyderabadi Bawarchi | C10: Hyderabad | D10: Biryani | E10: 4.3 | F10: 0.2
A11: 110 | B11: Puneri Thali House | C11: Pune | D11: North Indian | E11: 4 | F11: 0.18
A12: 111 | B12: Udupi Sagar | C12: Bangalore | D12: South Indian | E12: 4.4 | F12: 0.15
A13: 112 | B13: Tandoori Nights | C13: Delhi NCR | D13: North Indian | E13: 3.8 | F13: 0.22
... A21: 120 | B21: Cafe Goodluck | C21: Pune | D21: Fast Food | E21: 4.5 | F21: 0.18

Sheet Delivery_Partners
A1: partner_id | B1: partner_name | C1: base_city | D1: vehicle_type | E1: rating
A2: 201 | B2: Partner_201 | C2: Bangalore | D2: Motorcycle | E2: 4.7
A3: 202 | B3: Partner_202 | C3: Mumbai | D3: Motorcycle | E3: 4.1
A4: 203 | B4: Partner_203 | C4: Bangalore | D4: Electric Bike | E4: 4.7
A5: 204 | B5: Partner_204 | C5: Pune | D5: Motorcycle | E5: 4.5
A6: 205 | B6: Partner_205 | C6: Bangalore | D6: Motorcycle | E6: 4.1
A7: 206 | B7: Partner_206 | C7: Mumbai | D7: Electric Bike | E7: 4.5
A8: 207 | B8: Partner_207 | C8: Pune | D8: Motorcycle | E8: 4.6
A9: 208 | B9: Partner_208 | C9: Pune | D9: Scooter | E9: 4.2
A10: 209 | B10: Partner_209 | C10: Pune | D10: Scooter | E10: 4.7
A11: 210 | B11: Partner_210 | C11: Bangalore | D11: Motorcycle | E11: 4.6
A12: 211 | B12: Partner_211 | C12: Delhi NCR | D12: Scooter | E12: 4.1
A13: 212 | B13: Partner_212 | C13: Delhi NCR | D13: Motorcycle | E13: 4.1
... A31: 230 | B31: Partner_230 | C31: Delhi NCR | D31: Motorcycle | E31: 4.6

Sheet Cleaned_Orders
A1: order_id | B1: order_date | C1: order_time | D1: customer_id | E1: restaurant_id | F1: partner_id | G1: city | H1: cuisine_category | I1: order_value | J1: discount_amount | K1: delivery_fee | L1: platform_commission_pct | M1: platform_revenue | N1: delivery_distance_km | O1: delivery_time_mins | P1: payment_method | Q1: order_status | R1: customer_rating | S1: Order_YearMonth | T1: Customer_Tier_VLOOKUP | U1: Full_Order_Code | V1: Delivery_Speed_Category | W1: High_Value_Delivered_Flag | X1: Customer_Risk_Alert | Y1: Order_Fulfillment_Status | Z1: Safe_Rating_IFERROR
A2: ORD1001 | B2: 2025-07-26 | C2: 13:55:32 | D2: 1148 | E2: 115 | F2: 213 | G2: Bangalore | H2: Italian | I2: 221 | J2: 9.59 | K2: 31.5 | L2: 0.2 | M2: 52.08 | N2: 4.3 | O2: 32.5 | P2: Credit Card | Q2: Delivered | R2: 3 | S2: =TEXT(B2,"yyyy-mm") | T2: =VLOOKUP(D2,Customers!A:D,4,FALSE) | U2: =CONCATENATE(A2,"-",G2) | V2: =IF(N2="","",IF(N2<=30,"Fast (<30m)",IF(N2<=45,"Moderate (30-45m)","Delayed (>45m)"))) | W2: =IF(AND(I2>600,P2="Delivered"),"High Value Delivered","Standard") | X2: =IF(OR(N2>50,Q2<=2),"High Risk / Delayed","Normal") | Y2: =IF(NOT(P2="Cancelled"),"Fulfilled","Cancelled") | Z2: =IFERROR(Q2,0)
A3: ORD1002 | B3: 2025-01-27 | C3: 19:13:17 | D3: 1137 | E3: 106 | F3: 208 | G3: Pune | H3: South Indian | I3: 782 | J3: 0 | K3: 43.5 | L3: 0.15 | M3: 128.18 | N3: 6.7 | O3: 44.6 | P3: Cash on Delivery | Q3: Delivered | R3: 4 | S3: =TEXT(B3,"yyyy-mm") | T3: =VLOOKUP(D3,Customers!A:D,4,FALSE) | U3: =CONCATENATE(A3,"-",G3) | V3: =IF(N3="","",IF(N3<=30,"Fast (<30m)",IF(N3<=45,"Moderate (30-45m)","Delayed (>45m)"))) | W3: =IF(AND(I3>600,P3="Delivered"),"High Value Delivered","Standard") | X3: =IF(OR(N3>50,Q3<=2),"High Risk / Delayed","Normal") | Y3: =IF(NOT(P3="Cancelled"),"Fulfilled","Cancelled") | Z3: =IFERROR(Q3,0)
A4: ORD1003 | B4: 2025-11-19 | C4: 22:38:51 | D4: 1267 | E4: 115 | F4: 227 | G4: Bangalore | H4: Italian | I4: 465 | J4: 46.35 | K4: 27.5 | L4: 0.2 | M4: 99.88 | N4: 3.5 | O4: 29.4 | P4: UPI | Q4: Delivered | R4: 4 | S4: =TEXT(B4,"yyyy-mm") | T4: =VLOOKUP(D4,Customers!A:D,4,FALSE) | U4: =CONCATENATE(A4,"-",G4) | V4: =IF(N4="","",IF(N4<=30,"Fast (<30m)",IF(N4<=45,"Moderate (30-45m)","Delayed (>45m)"))) | W4: =IF(AND(I4>600,P4="Delivered"),"High Value Delivered","Standard") | X4: =IF(OR(N4>50,Q4<=2),"High Risk / Delayed","Normal") | Y4: =IF(NOT(P4="Cancelled"),"Fulfilled","Cancelled") | Z4: =IFERROR(Q4,0)
A5: ORD1004 | B5: 2025-02-28 | C5: 18:29:07 | D5: 1001 | E5: 119 | F5: 225 | G5: Hyderabad | H5: Biryani | I5: 883 | J5: 35.21 | K5: 43 | L5: 0.2 | M5: 187.35 | N5: 6.6 | O5: 41 | P5: Digital Wallet | Q5: Delivered | R5: 1 | S5: =TEXT(B5,"yyyy-mm") | T5: =VLOOKUP(D5,Customers!A:D,4,FALSE) | U5: =CONCATENATE(A5,"-",G5) | V5: =IF(N5="","",IF(N5<=30,"Fast (<30m)",IF(N5<=45,"Moderate (30-45m)","Delayed (>45m)"))) | W5: =IF(AND(I5>600,P5="Delivered"),"High Value Delivered","Standard") | X5: =IF(OR(N5>50,Q5<=2),"High Risk / Delayed","Normal") | Y5: =IF(NOT(P5="Cancelled"),"Fulfilled","Cancelled") | Z5: =IFERROR(Q5,0)
A6: ORD1005 | B6: 2025-08-30 | C6: 18:15:29 | D6: 1120 | E6: 120 | F6: 207 | G6: Pune | H6: Fast Food | I6: 784 | J6: 0 | K6: 25.5 | L6: 0.18 | M6: 147.5 | N6: 3.1 | O6: 23 | P6: Digital Wallet | Q6: Returned | R6: 3 | S6: =TEXT(B6,"yyyy-mm") | T6: =VLOOKUP(D6,Customers!A:D,4,FALSE) | U6: =CONCATENATE(A6,"-",G6) | V6: =IF(N6="","",IF(N6<=30,"Fast (<30m)",IF(N6<=45,"Moderate (30-45m)","Delayed (>45m)"))) | W6: =IF(AND(I6>600,P6="Delivered"),"High Value Delivered","Standard") | X6: =IF(OR(N6>50,Q6<=2),"High Risk / Delayed","Normal") | Y6: =IF(NOT(P6="Cancelled"),"Fulfilled","Cancelled") | Z6: =IFERROR(Q6,0)
A7: ORD1006 | B7: 2025-08-01 | C7: 19:21:59 | D7: 1247 | E7: 105 | F7: 210 | G7: Bangalore | H7: Chinese | I7: 739 | J7: 0 | K7: 29.5 | L7: 0.2 | M7: 155.18 | N7: 3.9 | O7: 35.9 | P7: Debit Card | Q7: Delivered | R7: 3 | S7: =TEXT(B7,"yyyy-mm") | T7: =VLOOKUP(D7,Customers!A:D,4,FALSE) | U7: =CONCATENATE(A7,"-",G7) | V7: =IF(N7="","",IF(N7<=30,"Fast (<30m)",IF(N7<=45,"Moderate (30-45m)","Delayed (>45m)"))) | W7: =IF(AND(I7>600,P7="Delivered"),"High Value Delivered","Standard") | X7: =IF(OR(N7>50,Q7<=2),"High Risk / Delayed","Normal") | Y7: =IF(NOT(P7="Cancelled"),"Fulfilled","Cancelled") | Z7: =IFERROR(Q7,0)
A8: ORD1007 | B8: 2025-10-03 | C8: 11:30:22 | D8: 1186 | E8: 102 | F8: 225 | G8: Hyderabad | H8: Biryani | I8: 560 | J8: 49.64 | K8: 28 | L8: 0.22 | M8: 130.2 | N8: 3.6 | O8: 28.6 | P8: Cash on Delivery | Q8: Delivered | R8: 4 | S8: =TEXT(B8,"yyyy-mm") | T8: =VLOOKUP(D8,Customers!A:D,4,FALSE) | U8: =CONCATENATE(A8,"-",G8) | V8: =IF(N8="","",IF(N8<=30,"Fast (<30m)",IF(N8<=45,"Moderate (30-45m)","Delayed (>45m)"))) | W8: =IF(AND(I8>600,P8="Delivered"),"High Value Delivered","Standard") | X8: =IF(OR(N8>50,Q8<=2),"High Risk / Delayed","Normal") | Y8: =IF(NOT(P8="Cancelled"),"Fulfilled","Cancelled") | Z8: =IFERROR(Q8,0)
A9: ORD1008 | B9: 2025-10-20 | C9: 23:24:14 | D9: 1079 | E9: 105 | F9: 213 | G9: Bangalore | H9: Chinese | I9: 640 | J9: 0 | K9: 26.5 | L9: 0.2 | M9: 134.62 | N9: 3.3 | O9: 28.8 | P9: Cash on Delivery | Q9: Delivered | R9: 2 | S9: =TEXT(B9,"yyyy-mm") | T9: =VLOOKUP(D9,Customers!A:D,4,FALSE) | U9: =CONCATENATE(A9,"-",G9) | V9: =IF(N9="","",IF(N9<=30,"Fast (<30m)",IF(N9<=45,"Moderate (30-45m)","Delayed (>45m)"))) | W9: =IF(AND(I9>600,P9="Delivered"),"High Value Delivered","Standard") | X9: =IF(OR(N9>50,Q9<=2),"High Risk / Delayed","Normal") | Y9: =IF(NOT(P9="Cancelled"),"Fulfilled","Cancelled") | Z9: =IFERROR(Q9,0)
A10: ORD1009 | B10: 2025-01-19 | C10: 17:08:32 | D10: 1005 | E10: 109 | F10: 225 | G10: Hyderabad | H10: Biryani | I10: 824 | J10: 0 | K10: 33 | L10: 0.2 | M10: 173.05 | N10: 4.6 | O10: 26.2 | P10: Cash on Delivery | Q10: Delivered | R10: 4 | S10: =TEXT(B10,"yyyy-mm") | T10: =VLOOKUP(D10,Customers!A:D,4,FALSE) | U10: =CONCATENATE(A10,"-",G10) | V10: =IF(N10="","",IF(N10<=30,"Fast (<30m)",IF(N10<=45,"Moderate (30-45m)","Delayed (>45m)"))) | W10: =IF(AND(I10>600,P10="Delivered"),"High Value Delivered","Standard") | X10: =IF(OR(N10>50,Q10<=2),"High Risk / Delayed","Normal") | Y10: =IF(NOT(P10="Cancelled"),"Fulfilled","Cancelled") | Z10: =IFERROR(Q10,0)
A11: ORD1010 | B11: 2025-01-08 | C11: 09:46:09 | D11: 1091 | E11: 116 | F11: 217 | G11: Pune | H11: Desserts | I11: 639 | J11: 49.58 | K11: 28 | L11: 0.25 | M11: 166.75 | N11: 3.6 | O11: 23 | P11: Debit Card | Q11: Delivered | R11: 4 | S11: =TEXT(B11,"yyyy-mm") | T11: =VLOOKUP(D11,Customers!A:D,4,FALSE) | U11: =CONCATENATE(A11,"-",G11) | V11: =IF(N11="","",IF(N11<=30,"Fast (<30m)",IF(N11<=45,"Moderate (30-45m)","Delayed (>45m)"))) | W11: =IF(AND(I11>600,P11="Delivered"),"High Value Delivered","Standard") | X11: =IF(OR(N11>50,Q11<=2),"High Risk / Delayed","Normal") | Y11: =IF(NOT(P11="Cancelled"),"Fulfilled","Cancelled") | Z11: =IFERROR(Q11,0)
A12: ORD1011 | B12: 2025-06-18 | C12: 11:54:43 | D12: 1275 | E12: 106 | F12: 214 | G12: Pune | H12: South Indian | I12: 766 | J12: 0 | K12: 34 | L12: 0.15 | M12: 123.4 | N12: 4.8 | O12: 32.5 | P12: Cash on Delivery | Q12: Delivered | R12: 4 | S12: =TEXT(B12,"yyyy-mm") | T12: =VLOOKUP(D12,Customers!A:D,4,FALSE) | U12: =CONCATENATE(A12,"-",G12) | V12: =IF(N12="","",IF(N12<=30,"Fast (<30m)",IF(N12<=45,"Moderate (30-45m)","Delayed (>45m)"))) | W12: =IF(AND(I12>600,P12="Delivered"),"High Value Delivered","Standard") | X12: =IF(OR(N12>50,Q12<=2),"High Risk / Delayed","Normal") | Y12: =IF(NOT(P12="Cancelled"),"Fulfilled","Cancelled") | Z12: =IFERROR(Q12,0)
A13: ORD1012 | B13: 2025-11-20 | C13: 10:43:58 | D13: 1264 | E13: 115 | F13: 203 | G13: Bangalore | H13: Italian | I13: 514 | J13: 30.71 | K13: 42 | L13: 0.2 | M13: 113.3 | N13: 6.4 | O13: 38.2 | P13: UPI | Q13: Delivered | R13: 4 | S13: =TEXT(B13,"yyyy-mm") | T13: =VLOOKUP(D13,Customers!A:D,4,FALSE) | U13: =CONCATENATE(A13,"-",G13) | V13: =IF(N13="","",IF(N13<=30,"Fast (<30m)",IF(N13<=45,"Moderate (30-45m)","Delayed (>45m)"))) | W13: =IF(AND(I13>600,P13="Delivered"),"High Value Delivered","Standard") | X13: =IF(OR(N13>50,Q13<=2),"High Risk / Delayed","Normal") | Y13: =IF(NOT(P13="Cancelled"),"Fulfilled","Cancelled") | Z13: =IFERROR(Q13,0)
... A18: ORD1017 | B18: 2025-07-16 | C18: 19:54:30 | D18: 1142 | E18: 114 | F18: 225 | G18: Hyderabad | H18: Biryani | I18: 329 | J18: 0 | K18: 33 | L18: 0.22 | M18: 80.63 | N18: 4.6 | O18: 35.6 | P18: Digital Wallet | Q18: Delivered | R18: 1 | S18: =TEXT(B18,"yyyy-mm") | T18: =VLOOKUP(D18,Customers!A:D,4,FALSE) | U18: =CONCATENATE(A18,"-",G18) | V18: =IF(N18="","",IF(N18<=30,"Fast (<30m)",IF(N18<=45,"Moderate (30-45m)","Delayed (>45m)"))) | W18: =IF(AND(I18>600,P18="Delivered"),"High Value Delivered","Standard") | X18: =IF(OR(N18>50,Q18<=2),"High Risk / Delayed","Normal") | Y18: =IF(NOT(P18="Cancelled"),"Fulfilled","Cancelled") | Z18: =IFERROR(Q18,0)
A19: ORD1018 | B19: 2025-12-04 | C19: 20:25:17 | D19: 1003 | E19: 116 | F19: 208 | G19: Pune | H19: Desserts | I19: 228 | J19: 20.43 | K19: 25 | L19: 0.25 | M19: 63.25 | N19: 2.2 | P19: UPI | Q19: Cancelled | S19: =TEXT(B19,"yyyy-mm") | T19: =VLOOKUP(D19,Customers!A:D,4,FALSE) | U19: =CONCATENATE(A19,"-",G19) | V19: =IF(N19="","",IF(N19<=30,"Fast (<30m)",IF(N19<=45,"Moderate (30-45m)","Delayed (>45m)"))) | W19: =IF(AND(I19>600,P19="Delivered"),"High Value Delivered","Standard") | X19: =IF(OR(N19>50,Q19<=2),"High Risk / Delayed","Normal") | Y19: =IF(NOT(P19="Cancelled"),"Fulfilled","Cancelled") | Z19: =IFERROR(Q19,0)
A20: ORD1019 | B20: 2025-11-07 | C20: 13:51:22 | D20: 1120 | E20: 106 | F20: 208 | G20: Pune | H20: South Indian | I20: 444 | J20: 22.05 | K20: 53 | L20: 0.15 | M20: 79.85 | N20: 8.6 | O20: 57.1 | P20: Credit Card | Q20: Delivered | R20: 3 | S20: =TEXT(B20,"yyyy-mm") | T20: =VLOOKUP(D20,Customers!A:D,4,FALSE) | U20: =CONCATENATE(A20,"-",G20) | V20: =IF(N20="","",IF(N20<=30,"Fast (<30m)",IF(N20<=45,"Moderate (30-45m)","Delayed (>45m)"))) | W20: =IF(AND(I20>600,P20="Delivered"),"High Value Delivered","Standard") | X20: =IF(OR(N20>50,Q20<=2),"High Risk / Delayed","Normal") | Y20: =IF(NOT(P20="Cancelled"),"Fulfilled","Cancelled") | Z20: =IFERROR(Q20,0)
A21: ORD1020 | B21: 2025-08-14 | C21: 13:02:37 | D21: 1245 | E21: 113 | F21: 222 | G21: Mumbai | H21: Fast Food | I21: 593 | J21: 4.28 | K21: 34 | L21: 0.18 | M21: 115.24 | N21: 4.8 | O21: 34.9 | P21: Cash on Delivery | Q21: Delivered | R21: 3 | S21: =TEXT(B21,"yyyy-mm") | T21: =VLOOKUP(D21,Customers!A:D,4,FALSE) | U21: =CONCATENATE(A21,"-",G21) | V21: =IF(N21="","",IF(N21<=30,"Fast (<30m)",IF(N21<=45,"Moderate (30-45m)","Delayed (>45m)"))) | W21: =IF(AND(I21>600,P21="Delivered"),"High Value Delivered","Standard") | X21: =IF(OR(N21>50,Q21<=2),"High Risk / Delayed","Normal") | Y21: =IF(NOT(P21="Cancelled"),"Fulfilled","Cancelled") | Z21: =IFERROR(Q21,0)
A22: ORD1021 | B22: 2025-03-09 | C22: 21:50:34 | D22: 1163 | E22: 117 | F22: 202 | G22: Mumbai | H22: Chinese | I22: 594 | J22: 51.77 | K22: 29 | L22: 0.2 | M22: 126.05 | N22: 3.8 | O22: 42.3 | P22: Credit Card | Q22: Delivered | R22: 3 | S22: =TEXT(B22,"yyyy-mm") | T22: =VLOOKUP(D22,Customers!A:D,4,FALSE) | U22: =CONCATENATE(A22,"-",G22) | V22: =IF(N22="","",IF(N22<=30,"Fast (<30m)",IF(N22<=45,"Moderate (30-45m)","Delayed (>45m)"))) | W22: =IF(AND(I22>600,P22="Delivered"),"High Value Delivered","Standard") | X22: =IF(OR(N22>50,Q22<=2),"High Risk / Delayed","Normal") | Y22: =IF(NOT(P22="Cancelled"),"Fulfilled","Cancelled") | Z22: =IFERROR(Q22,0)
A23: ORD1022 | B23: 2025-06-23 | C23: 19:51:07 | D23: 1022 | E23: 108 | F23: 228 | G23: Delhi NCR | H23: Fast Food | I23: 699 | J23: 7.87 | K23: 36.5 | L23: 0.18 | M23: 134.94 | N23: 5.3 | O23: 46.4 | P23: Cash on Delivery | Q23: Delivered | R23: 3 | S23: =TEXT(B23,"yyyy-mm") | T23: =VLOOKUP(D23,Customers!A:D,4,FALSE) | U23: =CONCATENATE(A23,"-",G23) | V23: =IF(N23="","",IF(N23<=30,"Fast (<30m)",IF(N23<=45,"Moderate (30-45m)","Delayed (>45m)"))) | W23: =IF(AND(I23>600,P23="Delivered"),"High Value Delivered","Standard") | X23: =IF(OR(N23>50,Q23<=2),"High Risk / Delayed","Normal") | Y23: =IF(NOT(P23="Cancelled"),"Fulfilled","Cancelled") | Z23: =IFERROR(Q23,0)
A24: ORD1023 | B24: 2025-01-08 | C24: 00:16:34 | D24: 1086 | E24: 104 | F24: 230 | G24: Delhi NCR | H24: Fast Food | I24: 346 | J24: 0 | K24: 26.5 | L24: 0.18 | M24: 68.9 | N24: 3.3 | O24: 28 | P24: Debit Card | Q24: Delivered | R24: 4 | S24: =TEXT(B24,"yyyy-mm") | T24: =VLOOKUP(D24,Customers!A:D,4,FALSE) | U24: =CONCATENATE(A24,"-",G24) | V24: =IF(N24="","",IF(N24<=30,"Fast (<30m)",IF(N24<=45,"Moderate (30-45m)","Delayed (>45m)"))) | W24: =IF(AND(I24>600,P24="Delivered"),"High Value Delivered","Standard") | X24: =IF(OR(N24>50,Q24<=2),"High Risk / Delayed","Normal") | Y24: =IF(NOT(P24="Cancelled"),"Fulfilled","Cancelled") | Z24: =IFERROR(Q24,0)
A25: ORD1024 | B25: 2025-12-12 | C25: 11:14:30 | D25: 1199 | E25: 109 | F25: 225 | G25: Hyderabad | H25: Biryani | I25: 503 | J25: 94.78 | K25: 0 | L25: 0.2 | M25: 100.6 | N25: 6.2 | O25: 35.4 | P25: Digital Wallet | Q25: Delivered | R25: 3 | S25: =TEXT(B25,"yyyy-mm") | T25: =VLOOKUP(D25,Customers!A:D,4,FALSE) | U25: =CONCATENATE(A25,"-",G25) | V25: =IF(N25="","",IF(N25<=30,"Fast (<30m)",IF(N25<=45,"Moderate (30-45m)","Delayed (>45m)"))) | W25: =IF(AND(I25>600,P25="Delivered"),"High Value Delivered","Standard") | X25: =IF(OR(N25>50,Q25<=2),"High Risk / Delayed","Normal") | Y25: =IF(NOT(P25="Cancelled"),"Fulfilled","Cancelled") | Z25: =IFERROR(Q25,0)
A26: ORD1025 | B26: 2025-11-22 | C26: 19:52:29 | D26: 1148 | E26: 111 | F26: 213 | G26: Bangalore | H26: South Indian | I26: 937 | J26: 0 | K26: 25 | L26: 0.15 | M26: 146.8 | N26: 1.6 | O26: 30.8 | P26: Credit Card | Q26: Delivered | R26: 5 | S26: =TEXT(B26,"yyyy-mm") | T26: =VLOOKUP(D26,Customers!A:D,4,FALSE) | U26: =CONCATENATE(A26,"-",G26) | V26: =IF(N26="","",IF(N26<=30,"Fast (<30m)",IF(N26<=45,"Moderate (30-45m)","Delayed (>45m)"))) | W26: =IF(AND(I26>600,P26="Delivered"),"High Value Delivered","Standard") | X26: =IF(OR(N26>50,Q26<=2),"High Risk / Delayed","Normal") | Y26: =IF(NOT(P26="Cancelled"),"Fulfilled","Cancelled") | Z26: =IFERROR(Q26,0)
A27: ORD1026 | B27: 2025-06-05 | C27: 11:31:07 | D27: 1062 | E27: 117 | F27: 206 | G27: Mumbai | H27: Chinese | I27: 319 | J27: 0 | K27: 25 | L27: 0.2 | M27: 70.05 | N27: 1.1 | O27: 20.6 | P27: Cash on Delivery | Q27: Delivered | R27: 5 | S27: =TEXT(B27,"yyyy-mm") | T27: =VLOOKUP(D27,Customers!A:D,4,FALSE) | U27: =CONCATENATE(A27,"-",G27) | V27: =IF(N27="","",IF(N27<=30,"Fast (<30m)",IF(N27<=45,"Moderate (30-45m)","Delayed (>45m)"))) | W27: =IF(AND(I27>600,P27="Delivered"),"High Value Delivered","Standard") | X27: =IF(OR(N27>50,Q27<=2),"High Risk / Delayed","Normal") | Y27: =IF(NOT(P27="Cancelled"),"Fulfilled","Cancelled") | Z27: =IFERROR(Q27,0)
A28: ORD1027 | B28: 2025-10-28 | C28: 09:47:46 | D28: 1246 | E28: 120 | F28: 214 | G28: Pune | H28: Fast Food | I28: 704 | J28: 99.61 | K28: 0 | L28: 0.18 | M28: 126.72 | N28: 3.5 | O28: 30.9 | P28: Cash on Delivery | Q28: Delivered | R28: 5 | S28: =TEXT(B28,"yyyy-mm") | T28: =VLOOKUP(D28,Customers!A:D,4,FALSE) | U28: =CONCATENATE(A28,"-",G28) | V28: =IF(N28="","",IF(N28<=30,"Fast (<30m)",IF(N28<=45,"Moderate (30-45m)","Delayed (>45m)"))) | W28: =IF(AND(I28>600,P28="Delivered"),"High Value Delivered","Standard") | X28: =IF(OR(N28>50,Q28<=2),"High Risk / Delayed","Normal") | Y28: =IF(NOT(P28="Cancelled"),"Fulfilled","Cancelled") | Z28: =IFERROR(Q28,0)
A29: ORD1028 | B29: 2025-12-20 | C29: 22:23:13 | D29: 1107 | E29: 107 | F29: 222 | G29: Mumbai | H29: Desserts | I29: 674 | J29: 0 | K29: 25 | L29: 0.25 | M29: 174.75 | N29: 2.5 | O29: 22.7 | P29: Debit Card | Q29: Delivered | R29: 3 | S29: =TEXT(B29,"yyyy-mm") | T29: =VLOOKUP(D29,Customers!A:D,4,FALSE) | U29: =CONCATENATE(A29,"-",G29) | V29: =IF(N29="","",IF(N29<=30,"Fast (<30m)",IF(N29<=45,"Moderate (30-45m)","Delayed (>45m)"))) | W29: =IF(AND(I29>600,P29="Delivered"),"High Value Delivered","Standard") | X29: =IF(OR(N29>50,Q29<=2),"High Risk / Delayed","Normal") | Y29: =IF(NOT(P29="Cancelled"),"Fulfilled","Cancelled") | Z29: =IFERROR(Q29,0)
A30: ORD1029 | B30: 2025-10-06 | C30: 20:57:41 | D30: 1223 | E30: 102 | F30: 225 | G30: Hyderabad | H30: Biryani | I30: 587 | J30: 0 | K30: 30.5 | L30: 0.22 | M30: 136.77 | N30: 4.1 | O30: 30.9 | P30: UPI | Q30: Delivered | R30: 1 | S30: =TEXT(B30,"yyyy-mm") | T30: =VLOOKUP(D30,Customers!A:D,4,FALSE) | U30: =CONCATENATE(A30,"-",G30) | V30: =IF(N30="","",IF(N30<=30,"Fast (<30m)",IF(N30<=45,"Moderate (30-45m)","Delayed (>45m)"))) | W30: =IF(AND(I30>600,P30="Delivered"),"High Value Delivered","Standard") | X30: =IF(OR(N30>50,Q30<=2),"High Risk / Delayed","Normal") | Y30: =IF(NOT(P30="Cancelled"),"Fulfilled","Cancelled") | Z30: =IFERROR(Q30,0)
A31: ORD1030 | B31: 2025-11-25 | C31: 13:40:38 | D31: 1236 | E31: 108 | F31: 212 | G31: Delhi NCR | H31: Fast Food | I31: 241 | J31: 12.9 | K31: 25 | L31: 0.18 | M31: 49.63 | N31: 3 | O31: 28.4 | P31: Credit Card | Q31: Delivered | R31: 4 | S31: =TEXT(B31,"yyyy-mm") | T31: =VLOOKUP(D31,Customers!A:D,4,FALSE) | U31: =CONCATENATE(A31,"-",G31) | V31: =IF(N31="","",IF(N31<=30,"Fast (<30m)",IF(N31<=45,"Moderate (30-45m)","Delayed (>45m)"))) | W31: =IF(AND(I31>600,P31="Delivered"),"High Value Delivered","Standard") | X31: =IF(OR(N31>50,Q31<=2),"High Risk / Delayed","Normal") | Y31: =IF(NOT(P31="Cancelled"),"Fulfilled","Cancelled") | Z31: =IFERROR(Q31,0)
... A54: ORD1053 | B54: 2025-06-08 | C54: 07:47:21 | D54: 1031 | E54: 107 | F54: 206 | G54: Mumbai | H54: Desserts | I54: 446 | J54: 32.7 | K54: 26 | L54: 0.25 | M54: 118 | N54: 3.2 | O54: 23.2 | P54: Digital Wallet | Q54: Delivered | R54: 5 | S54: =TEXT(B54,"yyyy-mm") | T54: =VLOOKUP(D54,Customers!A:D,4,FALSE) | U54: =CONCATENATE(A54,"-",G54) | V54: =IF(N54="","",IF(N54<=30,"Fast (<30m)",IF(N54<=45,"Moderate (30-45m)","Delayed (>45m)"))) | W54: =IF(AND(I54>600,P54="Delivered"),"High Value Delivered","Standard") | X54: =IF(OR(N54>50,Q54<=2),"High Risk / Delayed","Normal") | Y54: =IF(NOT(P54="Cancelled"),"Fulfilled","Cancelled") | Z54: =IFERROR(Q54,0)
A55: ORD1054 | B55: 2025-06-29 | C55: 21:46:52 | D55: 1231 | E55: 101 | F55: 203 | G55: Bangalore | H55: North Indian | I55: 880 | J55: 94.21 | K55: 25 | L55: 0.2 | M55: 182.25 | N55: 1.9 | P55: Credit Card | Q55: Cancelled | S55: =TEXT(B55,"yyyy-mm") | T55: =VLOOKUP(D55,Customers!A:D,4,FALSE) | U55: =CONCATENATE(A55,"-",G55) | V55: =IF(N55="","",IF(N55<=30,"Fast (<30m)",IF(N55<=45,"Moderate (30-45m)","Delayed (>45m)"))) | W55: =IF(AND(I55>600,P55="Delivered"),"High Value Delivered","Standard") | X55: =IF(OR(N55>50,Q55<=2),"High Risk / Delayed","Normal") | Y55: =IF(NOT(P55="Cancelled"),"Fulfilled","Cancelled") | Z55: =IFERROR(Q55,0)
A56: ORD1055 | B56: 2025-11-05 | C56: 20:09:48 | D56: 1152 | E56: 119 | F56: 215 | G56: Hyderabad | H56: Biryani | I56: 891 | J56: 0 | K56: 35 | L56: 0.2 | M56: 186.95 | N56: 5 | O56: 43.4 | P56: Cash on Delivery | Q56: Delivered | R56: 2 | S56: =TEXT(B56,"yyyy-mm") | T56: =VLOOKUP(D56,Customers!A:D,4,FALSE) | U56: =CONCATENATE(A56,"-",G56) | V56: =IF(N56="","",IF(N56<=30,"Fast (<30m)",IF(N56<=45,"Moderate (30-45m)","Delayed (>45m)"))) | W56: =IF(AND(I56>600,P56="Delivered"),"High Value Delivered","Standard") | X56: =IF(OR(N56>50,Q56<=2),"High Risk / Delayed","Normal") | Y56: =IF(NOT(P56="Cancelled"),"Fulfilled","Cancelled") | Z56: =IFERROR(Q56,0)
A57: ORD1056 | B57: 2025-11-18 | C57: 14:20:09 | D57: 1126 | E57: 119 | F57: 215 | G57: Hyderabad | H57: Biryani | I57: 670 | J57: 0 | K57: 42 | L57: 0.2 | M57: 144.5 | N57: 6.4 | O57: 41.2 | P57: Debit Card | Q57: Delivered | R57: 3 | S57: =TEXT(B57,"yyyy-mm") | T57: =VLOOKUP(D57,Customers!A:D,4,FALSE) | U57: =CONCATENATE(A57,"-",G57) | V57: =IF(N57="","",IF(N57<=30,"Fast (<30m)",IF(N57<=45,"Moderate (30-45m)","Delayed (>45m)"))) | W57: =IF(AND(I57>600,P57="Delivered"),"High Value Delivered","Standard") | X57: =IF(OR(N57>50,Q57<=2),"High Risk / Delayed","Normal") | Y57: =IF(NOT(P57="Cancelled"),"Fulfilled","Cancelled") | Z57: =IFERROR(Q57,0)
A58: ORD1057 | B58: 2025-09-17 | C58: 18:04:19 | D58: 1153 | E58: 105 | F58: 218 | G58: Bangalore | H58: Chinese | I58: 692 | J58: 0 | K58: 33.5 | L58: 0.2 | M58: 146.78 | N58: 4.7 | O58: 26.5 | P58: Debit Card | Q58: Delivered | R58: 5 | S58: =TEXT(B58,"yyyy-mm") | T58: =VLOOKUP(D58,Customers!A:D,4,FALSE) | U58: =CONCATENATE(A58,"-",G58) | V58: =IF(N58="","",IF(N58<=30,"Fast (<30m)",IF(N58<=45,"Moderate (30-45m)","Delayed (>45m)"))) | W58: =IF(AND(I58>600,P58="Delivered"),"High Value Delivered","Standard") | X58: =IF(OR(N58>50,Q58<=2),"High Risk / Delayed","Normal") | Y58: =IF(NOT(P58="Cancelled"),"Fulfilled","Cancelled") | Z58: =IFERROR(Q58,0)
A59: ORD1058 | B59: 2025-11-11 | C59: 22:38:32 | D59: 1085 | E59: 119 | F59: 215 | G59: Hyderabad | H59: Biryani | I59: 613 | J59: 0 | K59: 29.5 | L59: 0.2 | M59: 129.98 | N59: 3.9 | O59: 33.2 | P59: UPI | Q59: Delivered | R59: 5 | S59: =TEXT(B59,"yyyy-mm") | T59: =VLOOKUP(D59,Customers!A:D,4,FALSE) | U59: =CONCATENATE(A59,"-",G59) | V59: =IF(N59="","",IF(N59<=30,"Fast (<30m)",IF(N59<=45,"Moderate (30-45m)","Delayed (>45m)"))) | W59: =IF(AND(I59>600,P59="Delivered"),"High Value Delivered","Standard") | X59: =IF(OR(N59>50,Q59<=2),"High Risk / Delayed","Normal") | Y59: =IF(NOT(P59="Cancelled"),"Fulfilled","Cancelled") | Z59: =IFERROR(Q59,0)
A60: ORD1059 | B60: 2025-11-06 | C60: 21:30:32 | D60: 1109 | E60: 103 | F60: 206 | G60: Mumbai | H60: Italian | I60: 374 | J60: 13.48 | K60: 25 | L60: 0.18 | M60: 73.57 | N60: 3 | O60: 35.8 | P60: Debit Card | Q60: Delivered | R60: 4 | S60: =TEXT(B60,"yyyy-mm") | T60: =VLOOKUP(D60,Customers!A:D,4,FALSE) | U60: =CONCATENATE(A60,"-",G60) | V60: =IF(N60="","",IF(N60<=30,"Fast (<30m)",IF(N60<=45,"Moderate (30-45m)","Delayed (>45m)"))) | W60: =IF(AND(I60>600,P60="Delivered"),"High Value Delivered","Standard") | X60: =IF(OR(N60>50,Q60<=2),"High Risk / Delayed","Normal") | Y60: =IF(NOT(P60="Cancelled"),"Fulfilled","Cancelled") | Z60: =IFERROR(Q60,0)
A61: ORD1060 | B61: 2025-05-07 | C61: 00:45:28 | D61: 1211 | E61: 118 | F61: 228 | G61: Delhi NCR | H61: North Indian | I61: 669 | J61: 32.64 | K61: 25 | L61: 0.2 | M61: 140.05 | N61: 2.8 | O61: 24.8 | P61: Debit Card | Q61: Delivered | R61: 4 | S61: =TEXT(B61,"yyyy-mm") | T61: =VLOOKUP(D61,Customers!A:D,4,FALSE) | U61: =CONCATENATE(A61,"-",G61) | V61: =IF(N61="","",IF(N61<=30,"Fast (<30m)",IF(N61<=45,"Moderate (30-45m)","Delayed (>45m)"))) | W61: =IF(AND(I61>600,P61="Delivered"),"High Value Delivered","Standard") | X61: =IF(OR(N61>50,Q61<=2),"High Risk / Delayed","Normal") | Y61: =IF(NOT(P61="Cancelled"),"Fulfilled","Cancelled") | Z61: =IFERROR(Q61,0)
A62: ORD1061 | B62: 2025-12-14 | C62: 11:38:03 | D62: 1222 | E62: 114 | F62: 215 | G62: Hyderabad | H62: Biryani | I62: 866 | J62: 4.57 | K62: 42 | L62: 0.22 | M62: 201.02 | N62: 6.4 | O62: 37.8 | P62: Cash on Delivery | Q62: Delivered | R62: 3 | S62: =TEXT(B62,"yyyy-mm") | T62: =VLOOKUP(D62,Customers!A:D,4,FALSE) | U62: =CONCATENATE(A62,"-",G62) | V62: =IF(N62="","",IF(N62<=30,"Fast (<30m)",IF(N62<=45,"Moderate (30-45m)","Delayed (>45m)"))) | W62: =IF(AND(I62>600,P62="Delivered"),"High Value Delivered","Standard") | X62: =IF(OR(N62>50,Q62<=2),"High Risk / Delayed","Normal") | Y62: =IF(NOT(P62="Cancelled"),"Fulfilled","Cancelled") | Z62: =IFERROR(Q62,0)
A63: ORD1062 | B63: 2025-06-20 | C63: 12:05:37 | D63: 1128 | E63: 102 | F63: 216 | G63: Hyderabad | H63: Biryani | I63: 1035 | J63: 198.38 | K63: 0 | L63: 0.22 | M63: 227.7 | N63: 5.4 | O63: 36.1 | P63: Cash on Delivery | Q63: Delivered | R63: 4 | S63: =TEXT(B63,"yyyy-mm") | T63: =VLOOKUP(D63,Customers!A:D,4,FALSE) | U63: =CONCATENATE(A63,"-",G63) | V63: =IF(N63="","",IF(N63<=30,"Fast (<30m)",IF(N63<=45,"Moderate (30-45m)","Delayed (>45m)"))) | W63: =IF(AND(I63>600,P63="Delivered"),"High Value Delivered","Standard") | X63: =IF(OR(N63>50,Q63<=2),"High Risk / Delayed","Normal") | Y63: =IF(NOT(P63="Cancelled"),"Fulfilled","Cancelled") | Z63: =IFERROR(Q63,0)
A64: ORD1063 | B64: 2025-06-08 | C64: 12:35:24 | D64: 1092 | E64: 104 | F64: 230 | G64: Delhi NCR | H64: Fast Food | I64: 878 | J64: 92.56 | K64: 25 | L64: 0.18 | M64: 164.29 | N64: 1.8 | O64: 33.1 | P64: Digital Wallet | Q64: Delivered | R64: 5 | S64: =TEXT(B64,"yyyy-mm") | T64: =VLOOKUP(D64,Customers!A:D,4,FALSE) | U64: =CONCATENATE(A64,"-",G64) | V64: =IF(N64="","",IF(N64<=30,"Fast (<30m)",IF(N64<=45,"Moderate (30-45m)","Delayed (>45m)"))) | W64: =IF(AND(I64>600,P64="Delivered"),"High Value Delivered","Standard") | X64: =IF(OR(N64>50,Q64<=2),"High Risk / Delayed","Normal") | Y64: =IF(NOT(P64="Cancelled"),"Fulfilled","Cancelled") | Z64: =IFERROR(Q64,0)
A65: ORD1064 | B65: 2025-09-18 | C65: 06:23:01 | D65: 1119 | E65: 112 | F65: 228 | G65: Delhi NCR | H65: North Indian | I65: 770 | J65: 90.88 | K65: 0 | L65: 0.22 | M65: 169.4 | N65: 5.3 | O65: 30.9 | P65: Cash on Delivery | Q65: Delivered | R65: 4 | S65: =TEXT(B65,"yyyy-mm") | T65: =VLOOKUP(D65,Customers!A:D,4,FALSE) | U65: =CONCATENATE(A65,"-",G65) | V65: =IF(N65="","",IF(N65<=30,"Fast (<30m)",IF(N65<=45,"Moderate (30-45m)","Delayed (>45m)"))) | W65: =IF(AND(I65>600,P65="Delivered"),"High Value Delivered","Standard") | X65: =IF(OR(N65>50,Q65<=2),"High Risk / Delayed","Normal") | Y65: =IF(NOT(P65="Cancelled"),"Fulfilled","Cancelled") | Z65: =IFERROR(Q65,0)
A66: ORD1065 | B66: 2025-03-12 | C66: 14:09:04 | D66: 1209 | E66: 110 | F66: 214 | G66: Pune | H66: North Indian | I66: 522 | J66: 4.22 | K66: 25 | L66: 0.18 | M66: 100.21 | N66: 3 | O66: 36 | P66: Digital Wallet | Q66: Delivered | R66: 3 | S66: =TEXT(B66,"yyyy-mm") | T66: =VLOOKUP(D66,Customers!A:D,4,FALSE) | U66: =CONCATENATE(A66,"-",G66) | V66: =IF(N66="","",IF(N66<=30,"Fast (<30m)",IF(N66<=45,"Moderate (30-45m)","Delayed (>45m)"))) | W66: =IF(AND(I66>600,P66="Delivered"),"High Value Delivered","Standard") | X66: =IF(OR(N66>50,Q66<=2),"High Risk / Delayed","Normal") | Y66: =IF(NOT(P66="Cancelled"),"Fulfilled","Cancelled") | Z66: =IFERROR(Q66,0)
...

Sheet Raw_Orders_Audit
A1: order_id | B1: order_date | C1: order_time | D1: customer_id | E1: restaurant_id | F1: partner_id | G1: city | H1: cuisine_category | I1: order_value | J1: discount_amount | K1: delivery_fee | L1: platform_commission_pct | M1: platform_revenue | N1: delivery_distance_km | O1: delivery_time_mins | P1: payment_method | Q1: order_status | R1: customer_rating
A2: ORD1001 | B2: 2025-07-26 | C2: 13:55:32 | D2: 1148 | E2: 115 | F2: 213 | G2: Bangalore | H2: Italian | I2: 221 | J2: 9.59 | K2: 31.5 | L2: 0.2 | M2: 52.08 | N2: 4.3 | O2: 32.5 | P2: Credit Card | Q2: Delivered | R2: 3
A3: ORD1002 | B3: 2025-01-27 | C3: 19:13:17 | D3: 1137 | E3: 106 | F3: 208 | G3: Pune | H3: South Indian | I3: 782 | J3: 0 | K3: 43.5 | L3: 0.15 | M3: 128.18 | N3: 6.7 | O3: 44.6 | P3: Cash on Delivery | Q3: Delivered | R3: 4
A4: ORD1003 | B4: 2025-11-19 | C4: 22:38:51 | D4: 1267 | E4: 115 | F4: 227 | G4: Bangalore | H4: Italian | I4: 465 | J4: 46.35 | K4: 27.5 | L4: 0.2 | M4: 99.88 | N4: 3.5 | O4: 29.4 | P4: UPI | Q4: Delivered | R4: 4
A5: ORD1004 | B5: 2025-02-28 | C5: 18:29:07 | D5: 1001 | E5: 119 | F5: 225 | G5: Hyderabad | H5: Biryani | I5: 883 | J5: 35.21 | K5: 43 | L5: 0.2 | M5: 187.35 | N5: 6.6 | O5: 41 | P5: Digital Wallet | Q5: Delivered | R5: 1
A6: ORD1005 | B6: 2025-08-30 | C6: 18:15:29 | D6: 1120 | E6: 120 | F6: 207 | G6: Pune | H6: Fast Food | I6: 784 | J6: 0 | K6: 25.5 | L6: 0.18 | M6: 147.5 | N6: 3.1 | O6: 23 | P6: Digital Wallet | Q6: Returned | R6: 3
A7: ORD1006 | B7: 2025-08-01 | C7: 19:21:59 | D7: 1247 | E7: 105 | F7: 210 | G7: bangalore | H7: Chinese | I7: 739 | J7: 0 | K7: 29.5 | L7: 0.2 | M7: 155.18 | N7: 3.9 | O7: 35.9 | P7: Debit Card | Q7: Delivered | R7: 3
A8: ORD1007 | B8: 2025-10-03 | C8: 11:30:22 | D8: 1186 | E8: 102 | F8: 225 | G8: Hyderabad | H8: Biryani | I8: 560 | J8: 49.64 | K8: 28 | L8: 0.22 | M8: 130.2 | N8: 3.6 | O8: 28.6 | P8: Cash on Delivery | Q8: Delivered | R8: 4
A9: ORD1008 | B9: 2025-10-20 | C9: 23:24:14 | D9: 1079 | E9: 105 | F9: 213 | G9: Bangalore | H9: Chinese | I9: 640 | J9: 0 | K9: 26.5 | L9: 0.2 | M9: 134.62 | N9: 3.3 | O9: 28.8 | P9: Cash on Delivery | Q9: Delivered | R9: 2
A10: ORD1009 | B10: 2025-01-19 | C10: 17:08:32 | D10: 1005 | E10: 109 | F10: 225 | G10: Hyderabad | H10: Biryani | I10: 824 | J10: 0 | K10: 33 | L10: 0.2 | M10: 173.05 | N10: 4.6 | O10: 26.2 | P10: Cash on Delivery | Q10: Delivered | R10: 4
A11: ORD1010 | B11: 2025-01-08 | C11: 09:46:09 | D11: 1091 | E11: 116 | F11: 217 | G11: Pune | H11: Desserts | I11: 639 | J11: 49.58 | K11: 28 | L11: 0.25 | M11: 166.75 | N11: 3.6 | O11: 23 | P11: Debit Card | Q11: Delivered | R11: 4
A12: ORD1011 | B12: 2025-06-18 | C12: 11:54:43 | D12: 1275 | E12: 106 | F12: 214 | G12: Pune | H12: South Indian | I12: 766 | J12: 0 | K12: 34 | L12: 0.15 | M12: 123.4 | N12: 4.8 | O12: 32.5 | P12: Cash on Delivery | Q12: Delivered | R12: 4
A13: ORD1012 | B13: 2025-11-20 | C13: 10:43:58 | D13: 1264 | E13: 115 | F13: 203 | G13: Bangalore | H13: Italian | I13: 514 | J13: 30.71 | K13: 42 | L13: 0.2 | M13: 113.3 | N13: 6.4 | O13: 38.2 | P13: UPI | Q13: Delivered | R13: 4
... A18: ORD1017 | B18: 2025-07-16 | C18: 19:54:30 | D18: 1142 | E18: 114 | F18: 225 | G18: Hyderabad | H18: Biryani | I18: 329 | J18: 0 | K18: 33 | L18: 0.22 | M18: 80.63 | N18: 4.6 | O18: 35.6 | P18: Digital Wallet | Q18: Delivered | R18: 1
A19: ORD1018 | B19: 2025-12-04 | C19: 20:25:17 | D19: 1003 | E19: 116 | F19: 208 | G19: Pune | H19: Desserts | I19: 228 | J19: 20.43 | K19: 25 | L19: 0.25 | M19: 63.25 | N19: 2.2 | P19: UPI | Q19: Cancelled
A20: ORD1019 | B20: 2025-11-07 | C20: 13:51:22 | D20: 1120 | E20: 106 | F20: 208 | G20: Pune | H20: South Indian | I20: 444 | J20: 22.05 | K20: 53 | L20: 0.15 | M20: 79.85 | N20: 8.6 | O20: 57.1 | P20: Credit Card | Q20: Delivered | R20: 3
A21: ORD1020 | B21: 2025-08-14 | C21: 13:02:37 | D21: 1245 | E21: 113 | F21: 222 | G21: Mumbai | H21: Fast Food | I21: 593 | J21: 4.28 | K21: 34 | L21: 0.18 | M21: 115.24 | N21: 4.8 | O21: 34.9 | P21: Cash on Delivery | Q21: Delivered | R21: 3
A22: ORD1021 | B22: 2025-03-09 | C22: 21:50:34 | D22: 1163 | E22: 117 | F22: 202 | G22: Mumbai | H22: Chinese | I22: 594 | J22: 51.77 | K22: 29 | L22: 0.2 | M22: 126.05 | N22: 3.8 | O22: 42.3 | P22: Credit Card | Q22: Delivered
A23: ORD1022 | B23: 2025-06-23 | C23: 19:51:07 | D23: 1022 | E23: 108 | F23: 228 | G23: Delhi NCR | H23: Fast Food | I23: 699 | J23: 7.87 | K23: 36.5 | L23: 0.18 | M23: 134.94 | N23: 5.3 | O23: 46.4 | P23: Cash on Delivery | Q23: Delivered | R23: 3
A24: ORD1023 | B24: 2025-01-08 | C24: 00:16:34 | D24: 1086 | E24: 104 | F24: 230 | G24: Delhi NCR | H24: Fast Food | I24: 346 | J24: 0 | K24: 26.5 | L24: 0.18 | M24: 68.9 | N24: 3.3 | O24: 28 | P24: Debit Card | Q24: Delivered | R24: 4
A25: ORD1024 | B25: 2025-12-12 | C25: 11:14:30 | D25: 1199 | E25: 109 | F25: 225 | G25: Hyderabad | H25: Biryani | I25: 503 | J25: 94.78 | K25: 0 | L25: 0.2 | M25: 100.6 | N25: 6.2 | O25: 35.4 | P25: Digital Wallet | Q25: Delivered | R25: 3
A26: ORD1025 | B26: 2025-11-22 | C26: 19:52:29 | D26: 1148 | E26: 111 | F26: 213 | G26: Bangalore | H26: South Indian | I26: 937 | J26: 0 | K26: 25 | L26: 0.15 | M26: 146.8 | N26: 1.6 | O26: 30.8 | P26: Credit Card | Q26: Delivered | R26: 5
A27: ORD1026 | B27: 2025-06-05 | C27: 11:31:07 | D27: 1062 | E27: 117 | F27: 206 | G27: Mumbai | H27: Chinese | I27: 319 | J27: 0 | K27: 25 | L27: 0.2 | M27: 70.05 | N27: 1.1 | O27: 20.6 | P27: Cash on Delivery | Q27: Delivered | R27: 5
A28: ORD1027 | B28: 2025-10-28 | C28: 09:47:46 | D28: 1246 | E28: 120 | F28: 214 | G28: Pune | H28: Fast Food | I28: 704 | J28: 99.61 | K28: 0 | L28: 0.18 | M28: 126.72 | N28: 3.5 | O28: 30.9 | P28: Cash on Delivery | Q28: Delivered | R28: 5
A29: ORD1028 | B29: 2025-12-20 | C29: 22:23:13 | D29: 1107 | E29: 107 | F29: 222 | G29: Mumbai | H29: Desserts | I29: 674 | J29: 0 | K29: 25 | L29: 0.25 | M29: 174.75 | N29: 2.5 | O29: 22.7 | P29: Debit Card | Q29: Delivered | R29: 3
A30: ORD1029 | B30: 2025-10-06 | C30: 20:57:41 | D30: 1223 | E30: 102 | F30: 225 | G30: Hyderabad | H30: Biryani | I30: 587 | J30: 0 | K30: 30.5 | L30: 0.22 | M30: 136.77 | N30: 4.1 | O30: 30.9 | P30: UPI | Q30: Delivered | R30: 1
A31: ORD1030 | B31: 2025-11-25 | C31: 13:40:38 | D31: 1236 | E31: 108 | F31: 212 | G31: Delhi NCR | H31: Fast Food | I31: 241 | J31: 12.9 | K31: 25 | L31: 0.18 | M31: 49.63 | N31: 3 | O31: 28.4 | P31: Credit Card | Q31: Delivered | R31: 4
A32: ORD1031 | B32: 2025-10-28 | C32: 18:13:52 | D32: 1165 | E32: 117 | F32: 229 | G32: Mumbai | H32: Chinese | I32: 458 | J32: 0 | K32: 25 | L32: 0.2 | M32: 97.85 | N32: 1.6 | O32: 18.2 | P32: Digital Wallet | Q32: Delivered | R32: 5
A33: ORD1032 | B33: 2025-03-16 | C33: 12:08:34 | D33: 1263 | E33: 118 | F33: 212 | G33: Delhi NCR | H33: North Indian | I33: 476 | J33: 4.19 | K33: 38 | L33: 0.2 | M33: 104.7 | N33: 5.6 | O33: 42.3 | P33: Credit Card | Q33: Delivered | R33: 3
A34: ORD1033 | B34: 2025-05-02 | C34: 20:37:20 | D34: 1157 | E34: 102 | F34: 215 | G34: Hyderabad | H34: Biryani | I34: 236 | J34: 14.68 | K34: 65 | L34: 0.22 | M34: 68.17 | N34: 11 | O34: 54.4 | P34: Cash on Delivery | Q34: Delivered | R34: 3
... A54: ORD1053 | B54: 2025-06-08 | C54: 07:47:21 | D54: 1031 | E54: 107 | F54: 206 | G54: Mumbai | H54: Desserts | I54: 446 | J54: 32.7 | K54: 26 | L54: 0.25 | M54: 118 | N54: 3.2 | O54: 23.2 | P54: Digital Wallet | Q54: Delivered | R54: 5
A55: ORD1054 | B55: 2025-06-29 | C55: 21:46:52 | D55: 1231 | E55: 101 | F55: 203 | G55: Bangalore | H55: North Indian | I55: 880 | J55: 94.21 | K55: 25 | L55: 0.2 | M55: 182.25 | N55: 1.9 | P55: Credit Card | Q55: Cancelled
A56: ORD1055 | B56: 2025-11-05 | C56: 20:09:48 | D56: 1152 | E56: 119 | F56: 215 | G56: Hyderabad | H56: Biryani | I56: 891 | J56: 0 | K56: 35 | L56: 0.2 | M56: 186.95 | N56: 5 | O56: 43.4 | P56: Cash on Delivery | Q56: Delivered | R56: 2
A57: ORD1056 | B57: 2025-11-18 | C57: 14:20:09 | D57: 1126 | E57: 119 | F57: 215 | G57: Hyderabad | H57: Biryani | I57: 670 | J57: 0 | K57: 42 | L57: 0.2 | M57: 144.5 | N57: 6.4 | O57: 41.2 | P57: Debit Card | Q57: Delivered
A58: ORD1057 | B58: 2025-09-17 | C58: 18:04:19 | D58: 1153 | E58: 105 | F58: 218 | G58: Bangalore | H58: Chinese | I58: 692 | J58: 0 | K58: 33.5 | L58: 0.2 | M58: 146.78 | N58: 4.7 | O58: 26.5 | P58: Debit Card | Q58: Delivered | R58: 5
A59: ORD1058 | B59: 2025-11-11 | C59: 22:38:32 | D59: 1085 | E59: 119 | F59: 215 | G59: Hyderabad | H59: Biryani | I59: 613 | J59: 0 | K59: 29.5 | L59: 0.2 | M59: 129.98 | N59: 3.9 | O59: 33.2 | P59: UPI | Q59: Delivered | R59: 5
A60: ORD1059 | B60: 2025-11-06 | C60: 21:30:32 | D60: 1109 | E60: 103 | F60: 206 | G60: Mumbai | H60: Italian | I60: 374 | J60: 13.48 | K60: 25 | L60: 0.18 | M60: 73.57 | N60: 3 | O60: 35.8 | P60: Debit Card | Q60: Delivered | R60: 4
A61: ORD1060 | B61: 2025-05-07 | C61: 00:45:28 | D61: 1211 | E61: 118 | F61: 228 | G61: Delhi NCR | H61: North Indian | I61: 669 | J61: 32.64 | K61: 25 | L61: 0.2 | M61: 140.05 | N61: 2.8 | O61: 24.8 | P61: Debit Card | Q61: Delivered | R61: 4
A62: ORD1061 | B62: 2025-12-14 | C62: 11:38:03 | D62: 1222 | E62: 114 | F62: 215 | G62: Hyderabad | H62: Biryani | I62: 866 | J62: 4.57 | K62: 42 | L62: 0.22 | M62: 201.02 | N62: 6.4 | O62: 37.8 | P62: Cash on Delivery | Q62: Delivered | R62: 3
A63: ORD1062 | B63: 2025-06-20 | C63: 12:05:37 | D63: 1128 | E63: 102 | F63: 216 | G63: Hyderabad | H63: Biryani | I63: 1035 | J63: 198.38 | K63: 0 | L63: 0.22 | M63: 227.7 | N63: 5.4 | O63: 36.1 | P63: Cash on Delivery | Q63: Delivered | R63: 4
...

Sheet Statistical_Analysis
A1: FOOD DELIVERY BUSINESS ANALYTICS - STATISTICAL SUMMARY & IQR OUTLIER DETECTION
A3: Metric / Parameter | B3: Delivery Time (Minutes) | C3: Order Value (INR) | D3: Customer Rating | E3: Delivery Distance (km) | F3: Statistical Function Formula Used
A4: Total Observations (Count) | B4: =COUNT(Cleaned_Orders!N2:N2001) | C4: =COUNT(Cleaned_Orders!I2:I2001) | D4: =COUNT(Cleaned_Orders!Q2:Q2001) | E4: =COUNT(Cleaned_Orders!M2:M2001) | F4: COUNT(range)
A5: Mean (Average) | B5: =AVERAGE(Cleaned_Orders!N2:N2001) | C5: =AVERAGE(Cleaned_Orders!I2:I2001) | D5: =AVERAGE(Cleaned_Orders!Q2:Q2001) | E5: =AVERAGE(Cleaned_Orders!M2:M2001) | F5: AVERAGE(range)
A6: Median (50th Percentile) | B6: =MEDIAN(Cleaned_Orders!N2:N2001) | C6: =MEDIAN(Cleaned_Orders!I2:I2001) | D6: =MEDIAN(Cleaned_Orders!Q2:Q2001) | E6: =MEDIAN(Cleaned_Orders!M2:M2001) | F6: MEDIAN(range)
A7: Mode (Most Frequent) | B7: =MODE.SNGL(Cleaned_Orders!N2:N2001) | C7: =MODE.SNGL(Cleaned_Orders!I2:I2001) | D7: =MODE.SNGL(Cleaned_Orders!Q2:Q2001) | E7: =MODE.SNGL(Cleaned_Orders!M2:M2001) | F7: MODE.SNGL(range)
A8: Standard Deviation | B8: =STDEV.S(Cleaned_Orders!N2:N2001) | C8: =STDEV.S(Cleaned_Orders!I2:I2001) | D8: =STDEV.S(Cleaned_Orders!Q2:Q2001) | E8: =STDEV.S(Cleaned_Orders!M2:M2001) | F8: STDEV.S(range)
A9: Minimum | B9: =MIN(Cleaned_Orders!N2:N2001) | C9: =MIN(Cleaned_Orders!I2:I2001) | D9: =MIN(Cleaned_Orders!Q2:Q2001) | E9: =MIN(Cleaned_Orders!M2:M2001) | F9: MIN(range)
A10: Maximum | B10: =MAX(Cleaned_Orders!N2:N2001) | C10: =MAX(Cleaned_Orders!I2:I2001) | D10: =MAX(Cleaned_Orders!Q2:Q2001) | E10: =MAX(Cleaned_Orders!M2:M2001) | F10: MAX(range)
A11: Range (Max - Min) | B11: =B10-B9 | C11: =C10-C9 | D11: =D10-D9 | E11: =E10-E9 | F11: MAX - MIN
A12: First Quartile (Q1 - 25%) | B12: =QUARTILE.INC(Cleaned_Orders!N2:N2001, 1) | C12: =QUARTILE.INC(Cleaned_Orders!I2:I2001, 1) | D12: =QUARTILE.INC(Cleaned_Orders!Q2:Q2001, 1) | E12: =QUARTILE.INC(Cleaned_Orders!M2:M2001, 1) | F12: QUARTILE.INC(range, 1)
A13: Third Quartile (Q3 - 75%) | B13: =QUARTILE.INC(Cleaned_Orders!N2:N2001, 3) | C13: =QUARTILE.INC(Cleaned_Orders!I2:I2001, 3) | D13: =QUARTILE.INC(Cleaned_Orders!Q2:Q2001, 3) | E13: =QUARTILE.INC(Cleaned_Orders!M2:M2001, 3) | F13: QUARTILE.INC(range, 3)
A14: Interquartile Range (IQR) | B14: =B13-B12 | C14: =C13-C12 | D14: =D13-D12 | E14: =E13-E12 | F14: Q3 - Q1
A15: Lower Bound (Q1 - 1.5*IQR) | B15: =B12-(1.5*B14) | C15: =C12-(1.5*C14) | D15: =D12-(1.5*D14) | E15: =E12-(1.5*E14) | F15: Q1 - 1.5*IQR
A16: Upper Bound (Q3 + 1.5*IQR) | B16: =B13+(1.5*B14) | C16: =C13+(1.5*C14) | D16: =D13+(1.5*D14) | E16: =E13+(1.5*E14) | F16: Q3 + 1.5*IQR
A17: Outlier Count (Below Lower Bound) | B17: =COUNTIF(Cleaned_Orders!N2:N2001, "<"&B15) | C17: =COUNTIF(Cleaned_Orders!I2:I2001, "<"&C15) | D17: N/A | E17: =COUNTIF(Cleaned_Orders!M2:M2001, "<"&E15) | F17: COUNTIF(range, "<"&LowerBound)
A18: Outlier Count (Above Upper Bound) | B18: =COUNTIF(Cleaned_Orders!N2:N2001, ">"&B16) | C18: =COUNTIF(Cleaned_Orders!I2:I2001, ">"&C16) | D18: N/A | E18: =COUNTIF(Cleaned_Orders!M2:M2001, ">"&E16) | F18: COUNTIF(range, ">"&UpperBound)

Sheet Pivot_Summaries
A1: BUSINESS DIMENSION PERFORMANCE SUMMARIES (PIVOT ANALYTICS)
A3: City Performance Summary
A4: City | B4: Total Orders | C4: Delivered Orders | D4: Cancelled Orders | E4: Gross Sales (GMV) | F4: Platform Revenue | G4: Avg Delivery Time (m) | H4: Avg Rating
A5: Bangalore | B5: =COUNTIF(Cleaned_Orders!G2:G2001, "Bangalore") | C5: =COUNTIFS(Cleaned_Orders!G2:G2001, "Bangalore", Cleaned_Orders!P2:P2001, "Delivered") | D5: =COUNTIFS(Cleaned_Orders!G2:G2001, "Bangalore", Cleaned_Orders!P2:P2001, "Cancelled") | E5: =SUMIF(Cleaned_Orders!G2:G2001, "Bangalore", Cleaned_Orders!I2:I2001) | F5: =SUMIF(Cleaned_Orders!G2:G2001, "Bangalore", Cleaned_Orders!M2:M2001) | G5: =AVERAGEIFS(Cleaned_Orders!N2:N2001, Cleaned_Orders!G2:G2001, "Bangalore") | H5: =AVERAGEIFS(Cleaned_Orders!Q2:Q2001, Cleaned_Orders!G2:G2001, "Bangalore")
A6: Mumbai | B6: =COUNTIF(Cleaned_Orders!G2:G2001, "Mumbai") | C6: =COUNTIFS(Cleaned_Orders!G2:G2001, "Mumbai", Cleaned_Orders!P2:P2001, "Delivered") | D6: =COUNTIFS(Cleaned_Orders!G2:G2001, "Mumbai", Cleaned_Orders!P2:P2001, "Cancelled") | E6: =SUMIF(Cleaned_Orders!G2:G2001, "Mumbai", Cleaned_Orders!I2:I2001) | F6: =SUMIF(Cleaned_Orders!G2:G2001, "Mumbai", Cleaned_Orders!M2:M2001) | G6: =AVERAGEIFS(Cleaned_Orders!N2:N2001, Cleaned_Orders!G2:G2001, "Mumbai") | H6: =AVERAGEIFS(Cleaned_Orders!Q2:Q2001, Cleaned_Orders!G2:G2001, "Mumbai")
A7: Delhi NCR | B7: =COUNTIF(Cleaned_Orders!G2:G2001, "Delhi NCR") | C7: =COUNTIFS(Cleaned_Orders!G2:G2001, "Delhi NCR", Cleaned_Orders!P2:P2001, "Delivered") | D7: =COUNTIFS(Cleaned_Orders!G2:G2001, "Delhi NCR", Cleaned_Orders!P2:P2001, "Cancelled") | E7: =SUMIF(Cleaned_Orders!G2:G2001, "Delhi NCR", Cleaned_Orders!I2:I2001) | F7: =SUMIF(Cleaned_Orders!G2:G2001, "Delhi NCR", Cleaned_Orders!M2:M2001) | G7: =AVERAGEIFS(Cleaned_Orders!N2:N2001, Cleaned_Orders!G2:G2001, "Delhi NCR") | H7: =AVERAGEIFS(Cleaned_Orders!Q2:Q2001, Cleaned_Orders!G2:G2001, "Delhi NCR")
A8: Hyderabad | B8: =COUNTIF(Cleaned_Orders!G2:G2001, "Hyderabad") | C8: =COUNTIFS(Cleaned_Orders!G2:G2001, "Hyderabad", Cleaned_Orders!P2:P2001, "Delivered") | D8: =COUNTIFS(Cleaned_Orders!G2:G2001, "Hyderabad", Cleaned_Orders!P2:P2001, "Cancelled") | E8: =SUMIF(Cleaned_Orders!G2:G2001, "Hyderabad", Cleaned_Orders!I2:I2001) | F8: =SUMIF(Cleaned_Orders!G2:G2001, "Hyderabad", Cleaned_Orders!M2:M2001) | G8: =AVERAGEIFS(Cleaned_Orders!N2:N2001, Cleaned_Orders!G2:G2001, "Hyderabad") | H8: =AVERAGEIFS(Cleaned_Orders!Q2:Q2001, Cleaned_Orders!G2:G2001, "Hyderabad")
A9: Pune | B9: =COUNTIF(Cleaned_Orders!G2:G2001, "Pune") | C9: =COUNTIFS(Cleaned_Orders!G2:G2001, "Pune", Cleaned_Orders!P2:P2001, "Delivered") | D9: =COUNTIFS(Cleaned_Orders!G2:G2001, "Pune", Cleaned_Orders!P2:P2001, "Cancelled") | E9: =SUMIF(Cleaned_Orders!G2:G2001, "Pune", Cleaned_Orders!I2:I2001) | F9: =SUMIF(Cleaned_Orders!G2:G2001, "Pune", Cleaned_Orders!M2:M2001) | G9: =AVERAGEIFS(Cleaned_Orders!N2:N2001, Cleaned_Orders!G2:G2001, "Pune") | H9: =AVERAGEIFS(Cleaned_Orders!Q2:Q2001, Cleaned_Orders!G2:G2001, "Pune")
A10: Total / Overall | B10: =SUM(B5:B9) | C10: =SUM(C5:C9) | D10: =SUM(D5:D9) | E10: =SUM(E5:E9) | F10: =SUM(F5:F9) | G10: =AVERAGE(G5:G9) | H10: =AVERAGE(H5:H9)
A12: Cuisine Category Breakdown
A13: Cuisine Category | B13: Order Volume | C13: Gross Revenue (INR) | D13: Avg Order Value (AOV) | E13: Avg Customer Rating
A14: North Indian | B14: =COUNTIF(Cleaned_Orders!H2:H2001, "North Indian") | C14: =SUMIF(Cleaned_Orders!H2:H2001, "North Indian", Cleaned_Orders!I2:I2001) | D14: =AVERAGEIF(Cleaned_Orders!H2:H2001, "North Indian", Cleaned_Orders!I2:I2001) | E14: =AVERAGEIF(Cleaned_Orders!H2:H2001, "North Indian", Cleaned_Orders!Q2:Q2001)
A15: Biryani | B15: =COUNTIF(Cleaned_Orders!H2:H2001, "Biryani") | C15: =SUMIF(Cleaned_Orders!H2:H2001, "Biryani", Cleaned_Orders!I2:I2001) | D15: =AVERAGEIF(Cleaned_Orders!H2:H2001, "Biryani", Cleaned_Orders!I2:I2001) | E15: =AVERAGEIF(Cleaned_Orders!H2:H2001, "Biryani", Cleaned_Orders!Q2:Q2001)
A16: Fast Food | B16: =COUNTIF(Cleaned_Orders!H2:H2001, "Fast Food") | C16: =SUMIF(Cleaned_Orders!H2:H2001, "Fast Food", Cleaned_Orders!I2:I2001) | D16: =AVERAGEIF(Cleaned_Orders!H2:H2001, "Fast Food", Cleaned_Orders!I2:I2001) | E16: =AVERAGEIF(Cleaned_Orders!H2:H2001, "Fast Food", Cleaned_Orders!Q2:Q2001)
A17: South Indian | B17: =COUNTIF(Cleaned_Orders!H2:H2001, "South Indian") | C17: =SUMIF(Cleaned_Orders!H2:H2001, "South Indian", Cleaned_Orders!I2:I2001) | D17: =AVERAGEIF(Cleaned_Orders!H2:H2001, "South Indian", Cleaned_Orders!I2:I2001) | E17: =AVERAGEIF(Cleaned_Orders!H2:H2001, "South Indian", Cleaned_Orders!Q2:Q2001)
A18: Desserts | B18: =COUNTIF(Cleaned_Orders!H2:H2001, "Desserts") | C18: =SUMIF(Cleaned_Orders!H2:H2001, "Desserts", Cleaned_Orders!I2:I2001) | D18: =AVERAGEIF(Cleaned_Orders!H2:H2001, "Desserts", Cleaned_Orders!I2:I2001) | E18: =AVERAGEIF(Cleaned_Orders!H2:H2001, "Desserts", Cleaned_Orders!Q2:Q2001)
A19: Chinese | B19: =COUNTIF(Cleaned_Orders!H2:H2001, "Chinese") | C19: =SUMIF(Cleaned_Orders!H2:H2001, "Chinese", Cleaned_Orders!I2:I2001) | D19: =AVERAGEIF(Cleaned_Orders!H2:H2001, "Chinese", Cleaned_Orders!I2:I2001) | E19: =AVERAGEIF(Cleaned_Orders!H2:H2001, "Chinese", Cleaned_Orders!Q2:Q2001)
A20: Italian | B20: =COUNTIF(Cleaned_Orders!H2:H2001, "Italian") | C20: =SUMIF(Cleaned_Orders!H2:H2001, "Italian", Cleaned_Orders!I2:I2001) | D20: =AVERAGEIF(Cleaned_Orders!H2:H2001, "Italian", Cleaned_Orders!I2:I2001) | E20: =AVERAGEIF(Cleaned_Orders!H2:H2001, "Italian", Cleaned_Orders!Q2:Q2001)
A23: Customer Loyalty Tier Breakdown
A24: Customer Tier | B24: Total Orders | C24: Total Spent (INR) | D24: Avg Order Value (INR) | E24: Avg Discount Received
A25: Gold | B25: =COUNTIF(Cleaned_Orders!S2:S2001, "Gold") | C25: =SUMIF(Cleaned_Orders!S2:S2001, "Gold", Cleaned_Orders!I2:I2001) | D25: =AVERAGEIF(Cleaned_Orders!S2:S2001, "Gold", Cleaned_Orders!I2:I2001) | E25: =AVERAGEIF(Cleaned_Orders!S2:S2001, "Gold", Cleaned_Orders!J2:J2001)
A26: Silver | B26: =COUNTIF(Cleaned_Orders!S2:S2001, "Silver") | C26: =SUMIF(Cleaned_Orders!S2:S2001, "Silver", Cleaned_Orders!I2:I2001) | D26: =AVERAGEIF(Cleaned_Orders!S2:S2001, "Silver", Cleaned_Orders!I2:I2001) | E26: =AVERAGEIF(Cleaned_Orders!S2:S2001, "Silver", Cleaned_Orders!J2:J2001)
A27: Regular | B27: =COUNTIF(Cleaned_Orders!S2:S2001, "Regular") | C27: =SUMIF(Cleaned_Orders!S2:S2001, "Regular", Cleaned_Orders!I2:I2001) | D27: =AVERAGEIF(Cleaned_Orders!S2:S2001, "Regular", Cleaned_Orders!I2:I2001) | E27: =AVERAGEIF(Cleaned_Orders!S2:S2001, "Regular", Cleaned_Orders!J2:J2001)
